
  <robot name='vehicle_blue' canonical_link='chassis'>

    <material name="blue">
        <color rgba="0 0 1 1"/>
      </material>

    <material name="red">
        <color rgba="1 0 0 1"/>
      </material>

    <material name="green">
        <color rgba="0 1 0 1"/>
      </material>

    <plugin name='gz::sim::systems::DiffDrive' filename='gz-sim-diff-drive-system'>
      <left_joint>left_wheel_joint</left_joint>
      <right_joint>right_wheel_joint</right_joint>
      <wheel_separation>1.2</wheel_separation>
      <wheel_radius>0.4</wheel_radius>
      <odom_publish_frequency>30</odom_publish_frequency>
      <topic>cmd_vel</topic>
      <sim_time>true</sim_time>
      <real_time>true</real_time>
      <real_time_factor>true</real_time_factor>
    </plugin>
    <link name='chassis'>
      <pose relative_to='__model__'>0.5 0 0.40000000000000002 0 0 0</pose>
      <inertial>
        <mass value="1.14395"/>
        <inertia ixx="0.095328999999999997" ixy="0.0" ixz="0.0" iyy="0.38131700000000002" iyz="0.0" izz="0.47664600000000001"/>
      </inertial>
      <visual name='visual'>
        <geometry>
          <box size="2 1 0.5"/>
        </geometry>
        <material name="blue">
          <ambient>0 0 1 1</ambient>
          <diffuse>0 0 1 1</diffuse>
          <specular>0 0 1 1</specular>
        </material>
      </visual>
      <collision name='collision'>
        <geometry>
          <box size="2 1 0.5"/>
        </geometry>
      </collision>
    </link>
    <link name='left_wheel'>
      <pose relative_to='chassis'>-0.5 0.59999999999999998 0 -1.5707 0 0</pose>
      <inertial>
        <mass value="1"/>
        <inertia ixx="0.043333000000000003" ixy="0.0" ixz="0.0" iyy="0.043333000000000003" iyz="0.0" izz="0.080000000000000002"/>
      </inertial>
      <visual name='visual'>
        <geometry>
          <cylinder length="0.20000000000000001" radius="0.40000000000000002"/>
        </geometry>
        <material name="red">
          <ambient>1 0 0 1</ambient>
          <diffuse>1 0 0 1</diffuse>
          <specular>1 0 0 1</specular>
        </material>
      </visual>
      <collision name='collision'>
        <geometry>
          <cylinder length="0.20000000000000001" radius="0.40000000000000002"/>
        </geometry>
      </collision>
    </link>
    <link name='right_wheel'>
      <pose relative_to='chassis'>-0.5 -0.59999999999999998 0 -1.5707 0 0</pose>
      <inertial>
        <mass value="1"/>
        <inertia ixx="0.043333000000000003" ixy="0.0" ixz="0.0" iyy="0.043333000000000003" iyz="0.0" izz="0.080000000000000002"/>
      </inertial>
      <visual name='visual'>
        <geometry>
          <cylinder length="0.20000000000000001" radius="0.40000000000000002"/>
        </geometry>
        <material name="red">
          <ambient>1 0 0 1</ambient>
          <diffuse>1 0 0 1</diffuse>
          <specular>1 0 0 1</specular>
        </material>
      </visual>
      <collision name='collision'>
        <geometry>
          <cylinder length="0.20000000000000001" radius="0.40000000000000002"/>
        </geometry>
      </collision>
    </link>
    <frame name='caster_frame' attached_to='chassis'>
      <pose>0.80000000000000004 0 -0.20000000000000001 0 0 0</pose>
    </frame>

    <!-- Caster mount -->
  <link name="caster_mount">
    <visual>
      <geometry>
        <cylinder radius="0.3" length="0.2"/>
      </geometry>
      <origin xyz="0 0 0" rpy="0 0 0"/>
      <material name="red"/>
    </visual>
    <inertial>
      <mass value="1.0"/>
      <origin xyz="0 0 0" rpy="0 0 0"/>
      <inertia ixx="0.01" ixy="0" ixz="0"
               iyy="0.01" iyz="0"
               izz="0.01"/>
    </inertial>
  </link>
  <!-- Caster wheel -->
  <link name="caster_wheel">
    <visual>
      <geometry>
        <cylinder radius="0.3" length="0.2"/>
      </geometry>
      <origin xyz="0 0 0" rpy="1.5708 0 0"/> <!-- Rotate cylinder to roll on the ground -->
      <material name="red"/>
    </visual>
    <inertial>
      <mass value="0.5"/>
      <origin xyz="0 0 0" rpy="0 0 0"/>
      <inertia ixx="0.005" ixy="0" ixz="0"
               iyy="0.005" iyz="0"
               izz="0.005"/>
    </inertial>
  </link>

    <joint name='left_wheel_joint' type='revolute'>
      <pose relative_to='left_wheel'>0 0 0 0 0 0</pose>
      <parent link="chassis"/>
      <child link="left_wheel"/>
      <axis>
        <xyz expressed_in='__model__'>0 1 0</xyz>
        <limit>
          <lower>-1.7976900000000001e+308</lower>
          <upper>1.7976900000000001e+308</upper>
        </limit>
      </axis>
      <limit lower="-1.7976900000000001e+308" upper="1.7976900000000001e+308" effort="10" velocity="5"/>
    </joint>
    <joint name='right_wheel_joint' type='revolute'>
      <pose relative_to='right_wheel'>0 0 0 0 0 0</pose>
      <parent link="chassis"/>
      <child link="right_wheel"/>
      <axis>
        <xyz expressed_in='__model__'>0 1 0</xyz>
        <limit>
          <lower>-1.7976900000000001e+308</lower>
          <upper>1.7976900000000001e+308</upper>
        </limit>
      </axis>
      <limit lower="-1.7976900000000001e+308" upper="1.7976900000000001e+308" effort="10" velocity="5"/>
    </joint>
    <!--<joint name='caster_wheel' type='ball'>
      <parent>chassis</parent>
      <child>caster</child>
    </joint>-->

      <!-- Swivel joint: chassis → caster_mount -->
  <joint name="caster_swivel" type="continuous">
    <parent link="chassis"/>
    <child link="caster_mount"/>
    <origin xyz="0 -0.15 -0.05" rpy="0 0 0"/> <!-- adjust location under chassis -->
    <axis xyz="0 0 1"/>
  </joint>

  <!-- Roll joint: caster_mount → caster_wheel -->
  <joint name="caster_roll" type="continuous">
    <parent link="caster_mount"/>
    <child link="caster_wheel"/>
    <origin xyz="0 0 0" rpy="0 0 0"/>
    <axis xyz="0 1 0"/>
  </joint>

    <link name='lidar_frame'>
      <pose relative_to='chassis'>0 0 0.40000000000000002 0 0 0</pose>
      <visual name='visual'>
        <geometry>
          <cylinder length="0.29999999999999999" radius="0.29999999999999999"/>
        </geometry>
        <material name="red">
          <ambient>1 0 0 1</ambient>
          <diffuse>1 0 0 1</diffuse>
          <specular>1 0 0 1</specular>
        </material>
      </visual>
      <collision name='collision'>
        <geometry>
          <cylinder length="0.29999999999999999" radius="0.29999999999999999"/>
        </geometry>
      </collision>
      <inertial>
        <mass value="1"/>
        <inertia ixx="0.016" ixy="0.0" ixz="0.0" iyy="0.016" iyz="0.0" izz="0.016"/>
      </inertial>
      <sensor name='gpu_lidar' type='gpu_lidar'>
        <pose relative_to='lidar_frame'>0 0 0 0 0 0</pose>
        <topic>lidar</topic>
        <update_rate>10</update_rate>
        <ray>
          <scan>
            <horizontal>
              <samples>640</samples>
              <resolution>1</resolution>
              <min_angle>-1.396263</min_angle>
              <max_angle>1.396263</max_angle>
            </horizontal>
            <vertical>
              <samples>1</samples>
              <resolution>0.01</resolution>
              <min_angle>0</min_angle>
              <max_angle>0</max_angle>
            </vertical>
          </scan>
          <range>
            <min>0.080000000000000002</min>
            <max>10</max>
            <resolution>0.01</resolution>
          </range>
        </ray>
        <always_on>true</always_on>
        <visualize>true</visualize>
      </sensor>
    </link>
    <joint name='lidar_joint' type='fixed'>
      <parent link="chassis"/>
      <child link="lidar_frame"/>
    </joint>
    <plugin name='gz::sim::systems::Sensors' filename='gz-sim-sensors-system'>
      <render_engine>ogre2</render_engine>
      <sim_time>true</sim_time>
      <real_time>true</real_time>
      <real_time_factor>true</real_time_factor>
    </plugin>
  </robot>
